<?xml version="1.0" encoding="UTF-8"?>
<!-- Generated by org.testng.reporters.JUnitReportReporter -->
<testsuite hostname="PC-20161026ZCQN" name="org.webdriver.mindaiwebui.cases.LoginTest" tests="5" failures="4" timestamp="23 Jan 2017 01:50:32 GMT" time="15.869" errors="0">
  <testcase name="Login" time="3.741" classname="org.webdriver.mindaiwebui.cases.LoginTest">
    <failure type="java.lang.AssertionError" message="expected [0] but found [1]">
      <![CDATA[java.lang.AssertionError: expected [0] but found [1]
	at org.testng.Assert.fail(Assert.java:94)
	at org.testng.Assert.failNotEquals(Assert.java:496)
	at org.testng.Assert.assertEquals(Assert.java:125)
	at org.testng.Assert.assertEquals(Assert.java:372)
	at org.testng.Assert.assertEquals(Assert.java:382)
	at org.webdriver.mindaiwebui.utils.Assertion.VerityError(Assertion.java:1042)
	at org.webdriver.mindaiwebui.cases.LoginTest.Login(LoginTest.java:57)
	at sun.reflect.NativeMethodAccessorImpl.invoke0(Native Method)
	at sun.reflect.NativeMethodAccessorImpl.invoke(Unknown Source)
	at sun.reflect.DelegatingMethodAccessorImpl.invoke(Unknown Source)
	at java.lang.reflect.Method.invoke(Unknown Source)
	at org.testng.internal.MethodInvocationHelper.invokeMethod(MethodInvocationHelper.java:85)
	at org.testng.internal.Invoker.invokeMethod(Invoker.java:639)
	at org.testng.internal.Invoker.invokeTestMethod(Invoker.java:821)
	at org.testng.internal.Invoker.invokeTestMethods(Invoker.java:1131)
	at org.testng.internal.TestMethodWorker.invokeTestMethods(TestMethodWorker.java:125)
	at org.testng.internal.TestMethodWorker.run(TestMethodWorker.java:108)
	at org.testng.TestRunner.privateRun(TestRunner.java:773)
	at org.testng.TestRunner.run(TestRunner.java:623)
	at org.testng.SuiteRunner.runTest(SuiteRunner.java:357)
	at org.testng.SuiteRunner.runSequentially(SuiteRunner.java:352)
	at org.testng.SuiteRunner.privateRun(SuiteRunner.java:310)
	at org.testng.SuiteRunner.run(SuiteRunner.java:259)
	at org.testng.SuiteRunnerWorker.runSuite(SuiteRunnerWorker.java:52)
	at org.testng.SuiteRunnerWorker.run(SuiteRunnerWorker.java:86)
	at org.testng.TestNG.runSuitesSequentially(TestNG.java:1185)
	at org.testng.TestNG.runSuitesLocally(TestNG.java:1110)
	at org.testng.TestNG.run(TestNG.java:1018)
	at org.testng.remote.AbstractRemoteTestNG.run(AbstractRemoteTestNG.java:132)
	at org.testng.remote.RemoteTestNG.initAndRun(RemoteTestNG.java:236)
	at org.testng.remote.RemoteTestNG.main(RemoteTestNG.java:81)
]]>
    </failure>
  </testcase> <!-- Login -->
  <testcase name="Login" time="2.863" classname="org.webdriver.mindaiwebui.cases.LoginTest">
    <failure type="java.lang.AssertionError" message="expected [0] but found [1]">
      <![CDATA[java.lang.AssertionError: expected [0] but found [1]
	at org.testng.Assert.fail(Assert.java:94)
	at org.testng.Assert.failNotEquals(Assert.java:496)
	at org.testng.Assert.assertEquals(Assert.java:125)
	at org.testng.Assert.assertEquals(Assert.java:372)
	at org.testng.Assert.assertEquals(Assert.java:382)
	at org.webdriver.mindaiwebui.utils.Assertion.VerityError(Assertion.java:1042)
	at org.webdriver.mindaiwebui.cases.LoginTest.Login(LoginTest.java:57)
	at sun.reflect.NativeMethodAccessorImpl.invoke0(Native Method)
	at sun.reflect.NativeMethodAccessorImpl.invoke(Unknown Source)
	at sun.reflect.DelegatingMethodAccessorImpl.invoke(Unknown Source)
	at java.lang.reflect.Method.invoke(Unknown Source)
	at org.testng.internal.MethodInvocationHelper.invokeMethod(MethodInvocationHelper.java:85)
	at org.testng.internal.Invoker.invokeMethod(Invoker.java:639)
	at org.testng.internal.Invoker.invokeTestMethod(Invoker.java:821)
	at org.testng.internal.Invoker.invokeTestMethods(Invoker.java:1131)
	at org.testng.internal.TestMethodWorker.invokeTestMethods(TestMethodWorker.java:125)
	at org.testng.internal.TestMethodWorker.run(TestMethodWorker.java:108)
	at org.testng.TestRunner.privateRun(TestRunner.java:773)
	at org.testng.TestRunner.run(TestRunner.java:623)
	at org.testng.SuiteRunner.runTest(SuiteRunner.java:357)
	at org.testng.SuiteRunner.runSequentially(SuiteRunner.java:352)
	at org.testng.SuiteRunner.privateRun(SuiteRunner.java:310)
	at org.testng.SuiteRunner.run(SuiteRunner.java:259)
	at org.testng.SuiteRunnerWorker.runSuite(SuiteRunnerWorker.java:52)
	at org.testng.SuiteRunnerWorker.run(SuiteRunnerWorker.java:86)
	at org.testng.TestNG.runSuitesSequentially(TestNG.java:1185)
	at org.testng.TestNG.runSuitesLocally(TestNG.java:1110)
	at org.testng.TestNG.run(TestNG.java:1018)
	at org.testng.remote.AbstractRemoteTestNG.run(AbstractRemoteTestNG.java:132)
	at org.testng.remote.RemoteTestNG.initAndRun(RemoteTestNG.java:236)
	at org.testng.remote.RemoteTestNG.main(RemoteTestNG.java:81)
]]>
    </failure>
  </testcase> <!-- Login -->
  <testcase name="Login" time="2.678" classname="org.webdriver.mindaiwebui.cases.LoginTest"/>
  <testcase name="Login" time="2.949" classname="org.webdriver.mindaiwebui.cases.LoginTest">
    <failure type="java.lang.AssertionError" message="expected [0] but found [1]">
      <![CDATA[java.lang.AssertionError: expected [0] but found [1]
	at org.testng.Assert.fail(Assert.java:94)
	at org.testng.Assert.failNotEquals(Assert.java:496)
	at org.testng.Assert.assertEquals(Assert.java:125)
	at org.testng.Assert.assertEquals(Assert.java:372)
	at org.testng.Assert.assertEquals(Assert.java:382)
	at org.webdriver.mindaiwebui.utils.Assertion.VerityError(Assertion.java:1042)
	at org.webdriver.mindaiwebui.cases.LoginTest.Login(LoginTest.java:57)
	at sun.reflect.NativeMethodAccessorImpl.invoke0(Native Method)
	at sun.reflect.NativeMethodAccessorImpl.invoke(Unknown Source)
	at sun.reflect.DelegatingMethodAccessorImpl.invoke(Unknown Source)
	at java.lang.reflect.Method.invoke(Unknown Source)
	at org.testng.internal.MethodInvocationHelper.invokeMethod(MethodInvocationHelper.java:85)
	at org.testng.internal.Invoker.invokeMethod(Invoker.java:639)
	at org.testng.internal.Invoker.invokeTestMethod(Invoker.java:821)
	at org.testng.internal.Invoker.invokeTestMethods(Invoker.java:1131)
	at org.testng.internal.TestMethodWorker.invokeTestMethods(TestMethodWorker.java:125)
	at org.testng.internal.TestMethodWorker.run(TestMethodWorker.java:108)
	at org.testng.TestRunner.privateRun(TestRunner.java:773)
	at org.testng.TestRunner.run(TestRunner.java:623)
	at org.testng.SuiteRunner.runTest(SuiteRunner.java:357)
	at org.testng.SuiteRunner.runSequentially(SuiteRunner.java:352)
	at org.testng.SuiteRunner.privateRun(SuiteRunner.java:310)
	at org.testng.SuiteRunner.run(SuiteRunner.java:259)
	at org.testng.SuiteRunnerWorker.runSuite(SuiteRunnerWorker.java:52)
	at org.testng.SuiteRunnerWorker.run(SuiteRunnerWorker.java:86)
	at org.testng.TestNG.runSuitesSequentially(TestNG.java:1185)
	at org.testng.TestNG.runSuitesLocally(TestNG.java:1110)
	at org.testng.TestNG.run(TestNG.java:1018)
	at org.testng.remote.AbstractRemoteTestNG.run(AbstractRemoteTestNG.java:132)
	at org.testng.remote.RemoteTestNG.initAndRun(RemoteTestNG.java:236)
	at org.testng.remote.RemoteTestNG.main(RemoteTestNG.java:81)
]]>
    </failure>
  </testcase> <!-- Login -->
  <testcase name="login" time="3.638" classname="org.webdriver.mindaiwebui.cases.LoginTest">
    <failure type="java.lang.AssertionError" message="expected [0] but found [1]">
      <![CDATA[java.lang.AssertionError: expected [0] but found [1]
	at org.testng.Assert.fail(Assert.java:94)
	at org.testng.Assert.failNotEquals(Assert.java:496)
	at org.testng.Assert.assertEquals(Assert.java:125)
	at org.testng.Assert.assertEquals(Assert.java:372)
	at org.testng.Assert.assertEquals(Assert.java:382)
	at org.webdriver.mindaiwebui.utils.Assertion.VerityError(Assertion.java:1042)
	at org.webdriver.mindaiwebui.cases.LoginTest.login(LoginTest.java:34)
	at sun.reflect.NativeMethodAccessorImpl.invoke0(Native Method)
	at sun.reflect.NativeMethodAccessorImpl.invoke(Unknown Source)
	at sun.reflect.DelegatingMethodAccessorImpl.invoke(Unknown Source)
	at java.lang.reflect.Method.invoke(Unknown Source)
	at org.testng.internal.MethodInvocationHelper.invokeMethod(MethodInvocationHelper.java:85)
	at org.testng.internal.Invoker.invokeMethod(Invoker.java:639)
	at org.testng.internal.Invoker.invokeTestMethod(Invoker.java:821)
	at org.testng.internal.Invoker.invokeTestMethods(Invoker.java:1131)
	at org.testng.internal.TestMethodWorker.invokeTestMethods(TestMethodWorker.java:125)
	at org.testng.internal.TestMethodWorker.run(TestMethodWorker.java:108)
	at org.testng.TestRunner.privateRun(TestRunner.java:773)
	at org.testng.TestRunner.run(TestRunner.java:623)
	at org.testng.SuiteRunner.runTest(SuiteRunner.java:357)
	at org.testng.SuiteRunner.runSequentially(SuiteRunner.java:352)
	at org.testng.SuiteRunner.privateRun(SuiteRunner.java:310)
	at org.testng.SuiteRunner.run(SuiteRunner.java:259)
	at org.testng.SuiteRunnerWorker.runSuite(SuiteRunnerWorker.java:52)
	at org.testng.SuiteRunnerWorker.run(SuiteRunnerWorker.java:86)
	at org.testng.TestNG.runSuitesSequentially(TestNG.java:1185)
	at org.testng.TestNG.runSuitesLocally(TestNG.java:1110)
	at org.testng.TestNG.run(TestNG.java:1018)
	at org.testng.remote.AbstractRemoteTestNG.run(AbstractRemoteTestNG.java:132)
	at org.testng.remote.RemoteTestNG.initAndRun(RemoteTestNG.java:236)
	at org.testng.remote.RemoteTestNG.main(RemoteTestNG.java:81)
]]>
    </failure>
  </testcase> <!-- login -->
</testsuite> <!-- org.webdriver.mindaiwebui.cases.LoginTest -->
